<?xml version="1.0" ?>
<robot name="meca" xmlns:xacro="http://www.ros.org/wiki/xacro" >
    <!-- STEP 1 - Gazebo PLugin -->
  <xacro:include filename="$(find meca_description)/urdf/meca.gazebo" />
        
    <!-- STEP 2 - RViz colors -->
  <xacro:include filename="$(find meca_description)/urdf/materials.xacro" />
  <xacro:include filename="$(find meca_description)/urdf/lidar.xacro" /> 


    
  <!-- STEP 3 - RViz colors -->

  <link name="base_footprint"></link>
  <!-- STEP 2 - Robot chassis = base_link -->
  
  <joint name="base_footprint_joint" type="fixed">
  <origin xyz="0 0 0" rpy="0 0 0" />
  <parent link="base_footprint"/>
  <child link="base_link" />
  </joint>
  
      
  <link name="base_link"> 
    <inertial>
      <origin xyz="0 0 0" rpy="0 0 0"/>
      <mass value="30"/>
      <inertia ixx="0.193981" iyy="0.387085" izz="0.499531" ixy="-0.0" iyz="0.0" ixz="-0.000492"/>
    </inertial>
    <visual>
      <origin xyz="0 0 0" rpy="0 0 3.14"/>
      <geometry>
        <mesh filename="package://meca_description/meshes/base_link.stl" scale="0.001 0.001 0.001"/>
      </geometry>
          <material name="orange"/> 
    </visual>
    <collision>
      <origin xyz="0 0 0" rpy="0 0 3.14"/>
      <geometry>
        <mesh filename="package://meca_description/meshes/base_link.stl" scale="0.001 0.001 0.001"/>
      </geometry>
    </collision>
  </link>

   <link name="lidar_v1_1">
    <inertial>
      <origin xyz="0 0 -0.125" rpy="0 0 0"/>
      <mass value="0.05"/>
      <inertia ixx="0.0014" iyy="0.0014" izz="0.001721" ixy="0.0" iyz="-0.0" ixz="0.0"/>
    </inertial>
    <visual>
      <origin xyz="0 0 -0.125" rpy="0 0 0"/>
      <geometry>
        <mesh filename="package://meca_description/meshes/lidar_v1_1.stl" scale="0.001 0.001 0.001"/>
      </geometry>
       <material name="blue"/> 
    </visual>
    <collision>
      <origin xyz="0 0 -0.125" rpy="0 0 0"/>
      <geometry>
        <mesh filename="package://meca_description/meshes/lidar_v1_1.stl" scale="0.001 0.001 0.001"/>
      </geometry>
    </collision>
  </link>
 

  <link name="left_wheel_1">
    <inertial>
      <origin xyz="0 0.1 -0.075" rpy="0 0 0"/>
      <mass value="1.0"/>
      <inertia ixx="0.25" iyy="0.45" izz="0.55" ixy="0.0" iyz="0.0" ixz="0.0"/>   
    </inertial> 
    <visual>
      <origin xyz="0 0.1 -0.075" rpy="0 0 0"/>
      <geometry>
        <mesh filename="package://meca_description/meshes/left_wheel_1.stl" scale="0.001 0.001 0.001"/>
      </geometry>
    <material name="blue"/> 
    </visual>
    <collision>
      <origin xyz="0 0.1 -0.075" rpy="0 0 0"/>
      <geometry>
        <mesh filename="package://meca_description/meshes/left_wheel_1.stl" scale="0.001 0.001 0.001"/>
      </geometry>
    </collision>
  </link>

  <link name="right_wheel_1">
    <inertial>
      <origin xyz="0 -0.1 -0.075" rpy="0 0 0"/>
      <mass value="1.0"/>
      <inertia ixx="0.008" iyy="0.016" izz="0.008" ixy="0.0" iyz="0.0" ixz="0.0"/>    
    </inertial>
    <visual>
      <origin xyz="0 -0.1 -0.075" rpy="0 0 0"/>
      <geometry>
        <mesh filename="package://meca_description/meshes/right_wheel_1.stl" scale="0.001 0.001 0.001"/>
      </geometry>
   <material name="blue"/> 
    </visual>
    <collision>
      <origin xyz="0 -0.1 -0.075" rpy="0 0 0"/>
      <geometry>
        <mesh filename="package://meca_description/meshes/right_wheel_1.stl" scale="0.001 0.001 0.001"/>
      </geometry>
    </collision>
  </link>
     

    <joint name="joint_lidar" type="fixed">
    <origin xyz="0.0 0.0 0.125" rpy="0 0 0"/>
    <parent link="base_link"/>
    <child link="lidar_v1_1"/>
  </joint>
 
  <joint name="joint_left" type="continuous">
    <origin xyz="0 -0.1 0.075" rpy="0 0 0"/>
    <parent link="base_link"/>
    <child link="left_wheel_1"/>
    <axis xyz="0.0 1.0 0.0"/>
  </joint>

  <joint name="joint_right" type="continuous">
    <origin xyz="0.0 0.1 0.075" rpy="0 0 0"/>
    <parent link="base_link"/>
    <child link="right_wheel_1"/>
    <axis xyz="0.0 1.0 0.0"/>
  </joint>


</robot>
